Workbook

Sheet README
B2: Business Finance & Sales Performance Dashboard
B3: Fictional Company: Nexora Retail Solutions | Self-Initiated Portfolio Project
B5: PROJECT TITLE
B6: Business Finance & Sales Performance Dashboard - Nexora Retail Solutions (Fictional Company)
B8: DISCLAIMER
B9: This is a self-initiated portfolio project built with fictional company data. "Nexora Retail Solutions" is not a real company, and no real client, employer, or business relationship is implied anywhere in this file. All transactions, customers, and employees are randomly generated for demonstration purposes only. This project was created independently by Ankit Anand to practice and demonstrate Excel, financial analysis and data reporting skills for job applications.
B11: BUSINESS SCENARIO
B12: Nexora Retail Solutions is a fictional small-to-medium e-commerce retailer selling consumer electronics (audio devices, mobile accessories, computer peripherals, smart home devices, wearables and cameras) across 5 regions of India. The dataset simulates 12 months of order-level sales data (Aug 2025 - Jul 2026) so the workbook has a full seasonal cycle to analyse.
B14: PROBLEM STATEMENT
B15: Management has order-level data sitting in a flat spreadsheet but no simple way to see revenue, cost, profit and performance trends by month, region, category, product or salesperson. This project builds a clean data model and dashboard to turn that raw data into decision-ready KPIs and visuals.
B17: OBJECTIVE
B18: Build an Excel-based finance and sales analysis system that: (1) calculates revenue, cost of goods sold (COGS), gross profit, operating expense and net profit for every order using formulas; (2) summarises performance by month, region, category, product, salesperson and payment method; and (3) presents the results on a single-page, recruiter-friendly dashboard with KPI cards and charts.
... B41: WORKBOOK CONTENTS
B42: README | C42: This overview sheet.
B43: Raw Data | C43: 560-row transaction table (Excel Table) - the single source of truth for every formula in the workbook.
B44: Calculations | C44: Product cost master, category operating-expense table, and the monthly SUMIFS aggregation used by the dashboard charts.
B45: Pivot Analysis | C45: SUMIFS/COUNTIFS-based pivot-style summary tables by region, category, product, salesperson, month, payment method and order status.
B46: KPI Summary | C46: The single-cell headline KPIs, all formula-driven.
B47: Dashboard | C47: One-page management dashboard: KPI cards + 8 charts.
B48: Insights | C48: Formula-driven and written business insights, all directly supported by the dataset.

Sheet Calculations
A1: Calculations / Data Preparation
A2: Reference tables and monthly aggregations used by formulas throughout this workbook.
A4: Product Master | E4: Category Operating Expense %
A5: Product | B5: Category | C5: Unit Cost (Rs.) | E5: Category | F5: OpEx % of Revenue
A6: BassPro Wireless Earbuds | B6: Audio | C6: 650 | E6: Audio | F6: 0.1
A7: SoundWave Bluetooth Speaker | B7: Audio | C7: 900 | E7: Mobile Accessories | F7: 0.12
A8: StudioMax Over-Ear Headphones | B8: Audio | C8: 1400 | E8: Computer Peripherals | F8: 0.08
A9: EchoBeat Neckband | B9: Audio | C9: 450 | E9: Smart Home | F9: 0.11
A10: PowerCharge 20W Adapter | B10: Mobile Accessories | C10: 220 | E10: Wearables | F10: 0.09
A11: FlexiCable Type-C 1m | B11: Mobile Accessories | C11: 90 | E11: Cameras | F11: 0.075
A12: ArmorShield Phone Case | B12: Mobile Accessories | C12: 130
A13: MagGrip Phone Stand | B13: Mobile Accessories | C13: 150
A14: ClickPro Wireless Mouse | B14: Computer Peripherals | C14: 350
A15: TypeMaster Mechanical Keyboard | B15: Computer Peripherals | C15: 1600
A16: ViewClear 24-inch Monitor | B16: Computer Peripherals | C16: 7200
A17: HubConnect 7-in-1 USB-C Hub | B17: Computer Peripherals | C17: 900
A18: DeskLite LED Lamp | B18: Computer Peripherals | C18: 500
A19: SmartGlow LED Bulb (Wi-Fi) | B19: Smart Home | C19: 350
A20: HomeSecure Wi-Fi Camera | B20: Smart Home | C20: 2200
A21: SmartPlug Mini | B21: Smart Home | C21: 450
A22: VoiceHub Smart Speaker | B22: Smart Home | C22: 2600
A23: FitTrack Smart Band | B23: Wearables | C23: 1100
... A27: HomeView 360 Camera | B27: Cameras | C27: 3100
A30: Monthly Summary (SUMIFS aggregation from Raw Data)
A31: Month | B31: Period Start | C31: Period End (excl.) | D31: Total Revenue | E31: Total COGS | F31: Gross Profit | G31: Operating Expense | H31: Net Profit | I31: Total Orders
A32: Aug-25 | B32: 45870 | C32: 45901 | D32: =SUMIFS('Raw Data'!$M$2:$M$561,'Raw Data'!$B$2:$B$561,">="&B32,'Raw Data'!$B$2:$B$561,"<"&C32,'Raw Data'!$S$2:$S$561,"<>Cancelled",'Raw Data'!$S$2:$S$561,"<>Returned") -> 308354.91 | E32: =SUMIFS('Raw Data'!$N$2:$N$561,'Raw Data'!$B$2:$B$561,">="&B32,'Raw Data'!$B$2:$B$561,"<"&C32,'Raw Data'!$S$2:$S$561,"<>Cancelled",'Raw Data'!$S$2:$S$561,"<>Returned") -> 175480 | F32: =D32-E32 -> 132874.91 | G32: =SUMIFS('Raw Data'!$P$2:$P$561,'Raw Data'!$B$2:$B$561,">="&B32,'Raw Data'!$B$2:$B$561,"<"&C32,'Raw Data'!$S$2:$S$561,"<>Cancelled",'Raw Data'!$S$2:$S$561,"<>Returned") -> 26668.56 | H32: =F32-G32 -> 106206.35 | I32: =COUNTIFS('Raw Data'!$B$2:$B$561,">="&B32,'Raw Data'!$B$2:$B$561,"<"&C32,'Raw Data'!$S$2:$S$561,"<>Cancelled",'Raw Data'!$S$2:$S$561,"<>Returned") -> 37
A33: Sep-25 | B33: 45901 | C33: 45931 | D33: =SUMIFS('Raw Data'!$M$2:$M$561,'Raw Data'!$B$2:$B$561,">="&B33,'Raw Data'!$B$2:$B$561,"<"&C33,'Raw Data'!$S$2:$S$561,"<>Cancelled",'Raw Data'!$S$2:$S$561,"<>Returned") -> 240271.29 | E33: =SUMIFS('Raw Data'!$N$2:$N$561,'Raw Data'!$B$2:$B$561,">="&B33,'Raw Data'!$B$2:$B$561,"<"&C33,'Raw Data'!$S$2:$S$561,"<>Cancelled",'Raw Data'!$S$2:$S$561,"<>Returned") -> 141160 | F33: =D33-E33 -> 99111.288 | G33: =SUMIFS('Raw Data'!$P$2:$P$561,'Raw Data'!$B$2:$B$561,">="&B33,'Raw Data'!$B$2:$B$561,"<"&C33,'Raw Data'!$S$2:$S$561,"<>Cancelled",'Raw Data'!$S$2:$S$561,"<>Returned") -> 21229.21 | H33: =F33-G33 -> 77882.078 | I33: =COUNTIFS('Raw Data'!$B$2:$B$561,">="&B33,'Raw Data'!$B$2:$B$561,"<"&C33,'Raw Data'!$S$2:$S$561,"<>Cancelled",'Raw Data'!$S$2:$S$561,"<>Returned") -> 38
A34: Oct-25 | B34: 45931 | C34: 45962 | D34: =SUMIFS('Raw Data'!$M$2:$M$561,'Raw Data'!$B$2:$B$561,">="&B34,'Raw Data'!$B$2:$B$561,"<"&C34,'Raw Data'!$S$2:$S$561,"<>Cancelled",'Raw Data'!$S$2:$S$561,"<>Returned") -> 285740.49 | E34: =SUMIFS('Raw Data'!$N$2:$N$561,'Raw Data'!$B$2:$B$561,">="&B34,'Raw Data'!$B$2:$B$561,"<"&C34,'Raw Data'!$S$2:$S$561,"<>Cancelled",'Raw Data'!$S$2:$S$561,"<>Returned") -> 166830 | F34: =D34-E34 -> 118910.49 | G34: =SUMIFS('Raw Data'!$P$2:$P$561,'Raw Data'!$B$2:$B$561,">="&B34,'Raw Data'!$B$2:$B$561,"<"&C34,'Raw Data'!$S$2:$S$561,"<>Cancelled",'Raw Data'!$S$2:$S$561,"<>Returned") -> 25782.146 | H34: =F34-G34 -> 93128.341 | I34: =COUNTIFS('Raw Data'!$B$2:$B$561,">="&B34,'Raw Data'!$B$2:$B$561,"<"&C34,'Raw Data'!$S$2:$S$561,"<>Cancelled",'Raw Data'!$S$2:$S$561,"<>Returned") -> 46
A35: Nov-25 | B35: 45962 | C35: 45992 | D35: =SUMIFS('Raw Data'!$M$2:$M$561,'Raw Data'!$B$2:$B$561,">="&B35,'Raw Data'!$B$2:$B$561,"<"&C35,'Raw Data'!$S$2:$S$561,"<>Cancelled",'Raw Data'!$S$2:$S$561,"<>Returned") -> 194015.85 | E35: =SUMIFS('Raw Data'!$N$2:$N$561,'Raw Data'!$B$2:$B$561,">="&B35,'Raw Data'!$B$2:$B$561,"<"&C35,'Raw Data'!$S$2:$S$561,"<>Cancelled",'Raw Data'!$S$2:$S$561,"<>Returned") -> 114790 | F35: =D35-E35 -> 79225.848 | G35: =SUMIFS('Raw Data'!$P$2:$P$561,'Raw Data'!$B$2:$B$561,">="&B35,'Raw Data'!$B$2:$B$561,"<"&C35,'Raw Data'!$S$2:$S$561,"<>Cancelled",'Raw Data'!$S$2:$S$561,"<>Returned") -> 17783.191 | H35: =F35-G35 -> 61442.657 | I35: =COUNTIFS('Raw Data'!$B$2:$B$561,">="&B35,'Raw Data'!$B$2:$B$561,"<"&C35,'Raw Data'!$S$2:$S$561,"<>Cancelled",'Raw Data'!$S$2:$S$561,"<>Returned") -> 37
A36: Dec-25 | B36: 45992 | C36: 46023 | D36: =SUMIFS('Raw Data'!$M$2:$M$561,'Raw Data'!$B$2:$B$561,">="&B36,'Raw Data'!$B$2:$B$561,"<"&C36,'Raw Data'!$S$2:$S$561,"<>Cancelled",'Raw Data'!$S$2:$S$561,"<>Returned") -> 211208.9 | E36: =SUMIFS('Raw Data'!$N$2:$N$561,'Raw Data'!$B$2:$B$561,">="&B36,'Raw Data'!$B$2:$B$561,"<"&C36,'Raw Data'!$S$2:$S$561,"<>Cancelled",'Raw Data'!$S$2:$S$561,"<>Returned") -> 124490 | F36: =D36-E36 -> 86718.905 | G36: =SUMIFS('Raw Data'!$P$2:$P$561,'Raw Data'!$B$2:$B$561,">="&B36,'Raw Data'!$B$2:$B$561,"<"&C36,'Raw Data'!$S$2:$S$561,"<>Cancelled",'Raw Data'!$S$2:$S$561,"<>Returned") -> 18828.729 | H36: =F36-G36 -> 67890.176 | I36: =COUNTIFS('Raw Data'!$B$2:$B$561,">="&B36,'Raw Data'!$B$2:$B$561,"<"&C36,'Raw Data'!$S$2:$S$561,"<>Cancelled",'Raw Data'!$S$2:$S$561,"<>Returned") -> 38
A37: Jan-26 | B37: 46023 | C37: 46054 | D37: =SUMIFS('Raw Data'!$M$2:$M$561,'Raw Data'!$B$2:$B$561,">="&B37,'Raw Data'!$B$2:$B$561,"<"&C37,'Raw Data'!$S$2:$S$561,"<>Cancelled",'Raw Data'!$S$2:$S$561,"<>Returned") -> 267567.12 | E37: =SUMIFS('Raw Data'!$N$2:$N$561,'Raw Data'!$B$2:$B$561,">="&B37,'Raw Data'!$B$2:$B$561,"<"&C37,'Raw Data'!$S$2:$S$561,"<>Cancelled",'Raw Data'!$S$2:$S$561,"<>Returned") -> 154320 | F37: =D37-E37 -> 113247.12 | G37: =SUMIFS('Raw Data'!$P$2:$P$561,'Raw Data'!$B$2:$B$561,">="&B37,'Raw Data'!$B$2:$B$561,"<"&C37,'Raw Data'!$S$2:$S$561,"<>Cancelled",'Raw Data'!$S$2:$S$561,"<>Returned") -> 23979.948 | H37: =F37-G37 -> 89267.171 | I37: =COUNTIFS('Raw Data'!$B$2:$B$561,">="&B37,'Raw Data'!$B$2:$B$561,"<"&C37,'Raw Data'!$S$2:$S$561,"<>Cancelled",'Raw Data'!$S$2:$S$561,"<>Returned") -> 45
A38: Feb-26 | B38: 46054 | C38: 46082 | D38: =SUMIFS('Raw Data'!$M$2:$M$561,'Raw Data'!$B$2:$B$561,">="&B38,'Raw Data'!$B$2:$B$561,"<"&C38,'Raw Data'!$S$2:$S$561,"<>Cancelled",'Raw Data'!$S$2:$S$561,"<>Returned") -> 261061.41 | E38: =SUMIFS('Raw Data'!$N$2:$N$561,'Raw Data'!$B$2:$B$561,">="&B38,'Raw Data'!$B$2:$B$561,"<"&C38,'Raw Data'!$S$2:$S$561,"<>Cancelled",'Raw Data'!$S$2:$S$561,"<>Returned") -> 151130 | F38: =D38-E38 -> 109931.41 | G38: =SUMIFS('Raw Data'!$P$2:$P$561,'Raw Data'!$B$2:$B$561,">="&B38,'Raw Data'!$B$2:$B$561,"<"&C38,'Raw Data'!$S$2:$S$561,"<>Cancelled",'Raw Data'!$S$2:$S$561,"<>Returned") -> 23218.495 | H38: =F38-G38 -> 86712.917 | I38: =COUNTIFS('Raw Data'!$B$2:$B$561,">="&B38,'Raw Data'!$B$2:$B$561,"<"&C38,'Raw Data'!$S$2:$S$561,"<>Cancelled",'Raw Data'!$S$2:$S$561,"<>Returned") -> 38
A39: Mar-26 | B39: 46082 | C39: 46113 | D39: =SUMIFS('Raw Data'!$M$2:$M$561,'Raw Data'!$B$2:$B$561,">="&B39,'Raw Data'!$B$2:$B$561,"<"&C39,'Raw Data'!$S$2:$S$561,"<>Cancelled",'Raw Data'!$S$2:$S$561,"<>Returned") -> 293993.19 | E39: =SUMIFS('Raw Data'!$N$2:$N$561,'Raw Data'!$B$2:$B$561,">="&B39,'Raw Data'!$B$2:$B$561,"<"&C39,'Raw Data'!$S$2:$S$561,"<>Cancelled",'Raw Data'!$S$2:$S$561,"<>Returned") -> 174440 | F39: =D39-E39 -> 119553.19 | G39: =SUMIFS('Raw Data'!$P$2:$P$561,'Raw Data'!$B$2:$B$561,">="&B39,'Raw Data'!$B$2:$B$561,"<"&C39,'Raw Data'!$S$2:$S$561,"<>Cancelled",'Raw Data'!$S$2:$S$561,"<>Returned") -> 27773.349 | H39: =F39-G39 -> 91779.845 | I39: =COUNTIFS('Raw Data'!$B$2:$B$561,">="&B39,'Raw Data'!$B$2:$B$561,"<"&C39,'Raw Data'!$S$2:$S$561,"<>Cancelled",'Raw Data'!$S$2:$S$561,"<>Returned") -> 43
A40: Apr-26 | B40: 46113 | C40: 46143 | D40: =SUMIFS('Raw Data'!$M$2:$M$561,'Raw Data'!$B$2:$B$561,">="&B40,'Raw Data'!$B$2:$B$561,"<"&C40,'Raw Data'!$S$2:$S$561,"<>Cancelled",'Raw Data'!$S$2:$S$561,"<>Returned") -> 384240.26 | E40: =SUMIFS('Raw Data'!$N$2:$N$561,'Raw Data'!$B$2:$B$561,">="&B40,'Raw Data'!$B$2:$B$561,"<"&C40,'Raw Data'!$S$2:$S$561,"<>Cancelled",'Raw Data'!$S$2:$S$561,"<>Returned") -> 227120 | F40: =D40-E40 -> 157120.26 | G40: =SUMIFS('Raw Data'!$P$2:$P$561,'Raw Data'!$B$2:$B$561,">="&B40,'Raw Data'!$B$2:$B$561,"<"&C40,'Raw Data'!$S$2:$S$561,"<>Cancelled",'Raw Data'!$S$2:$S$561,"<>Returned") -> 32744.752 | H40: =F40-G40 -> 124375.5 | I40: =COUNTIFS('Raw Data'!$B$2:$B$561,">="&B40,'Raw Data'!$B$2:$B$561,"<"&C40,'Raw Data'!$S$2:$S$561,"<>Cancelled",'Raw Data'!$S$2:$S$561,"<>Returned") -> 44
A41: May-26 | B41: 46143 | C41: 46174 | D41: =SUMIFS('Raw Data'!$M$2:$M$561,'Raw Data'!$B$2:$B$561,">="&B41,'Raw Data'!$B$2:$B$561,"<"&C41,'Raw Data'!$S$2:$S$561,"<>Cancelled",'Raw Data'!$S$2:$S$561,"<>Returned") -> 248761.62 | E41: =SUMIFS('Raw Data'!$N$2:$N$561,'Raw Data'!$B$2:$B$561,">="&B41,'Raw Data'!$B$2:$B$561,"<"&C41,'Raw Data'!$S$2:$S$561,"<>Cancelled",'Raw Data'!$S$2:$S$561,"<>Returned") -> 146030 | F41: =D41-E41 -> 102731.62 | G41: =SUMIFS('Raw Data'!$P$2:$P$561,'Raw Data'!$B$2:$B$561,">="&B41,'Raw Data'!$B$2:$B$561,"<"&C41,'Raw Data'!$S$2:$S$561,"<>Cancelled",'Raw Data'!$S$2:$S$561,"<>Returned") -> 22022.089 | H41: =F41-G41 -> 80709.528 | I41: =COUNTIFS('Raw Data'!$B$2:$B$561,">="&B41,'Raw Data'!$B$2:$B$561,"<"&C41,'Raw Data'!$S$2:$S$561,"<>Cancelled",'Raw Data'!$S$2:$S$561,"<>Returned") -> 40
A42: Jun-26 | B42: 46174 | C42: 46204 | D42: =SUMIFS('Raw Data'!$M$2:$M$561,'Raw Data'!$B$2:$B$561,">="&B42,'Raw Data'!$B$2:$B$561,"<"&C42,'Raw Data'!$S$2:$S$561,"<>Cancelled",'Raw Data'!$S$2:$S$561,"<>Returned") -> 326130.33 | E42: =SUMIFS('Raw Data'!$N$2:$N$561,'Raw Data'!$B$2:$B$561,">="&B42,'Raw Data'!$B$2:$B$561,"<"&C42,'Raw Data'!$S$2:$S$561,"<>Cancelled",'Raw Data'!$S$2:$S$561,"<>Returned") -> 189610 | F42: =D42-E42 -> 136520.33 | G42: =SUMIFS('Raw Data'!$P$2:$P$561,'Raw Data'!$B$2:$B$561,">="&B42,'Raw Data'!$B$2:$B$561,"<"&C42,'Raw Data'!$S$2:$S$561,"<>Cancelled",'Raw Data'!$S$2:$S$561,"<>Returned") -> 27462.423 | H42: =F42-G42 -> 109057.91 | I42: =COUNTIFS('Raw Data'!$B$2:$B$561,">="&B42,'Raw Data'!$B$2:$B$561,"<"&C42,'Raw Data'!$S$2:$S$561,"<>Cancelled",'Raw Data'!$S$2:$S$561,"<>Returned") -> 34
A43: Jul-26 | B43: 46204 | C43: 46235 | D43: =SUMIFS('Raw Data'!$M$2:$M$561,'Raw Data'!$B$2:$B$561,">="&B43,'Raw Data'!$B$2:$B$561,"<"&C43,'Raw Data'!$S$2:$S$561,"<>Cancelled",'Raw Data'!$S$2:$S$561,"<>Returned") -> 261369.55 | E43: =SUMIFS('Raw Data'!$N$2:$N$561,'Raw Data'!$B$2:$B$561,">="&B43,'Raw Data'!$B$2:$B$561,"<"&C43,'Raw Data'!$S$2:$S$561,"<>Cancelled",'Raw Data'!$S$2:$S$561,"<>Returned") -> 152080 | F43: =D43-E43 -> 109289.55 | G43: =SUMIFS('Raw Data'!$P$2:$P$561,'Raw Data'!$B$2:$B$561,">="&B43,'Raw Data'!$B$2:$B$561,"<"&C43,'Raw Data'!$S$2:$S$561,"<>Cancelled",'Raw Data'!$S$2:$S$561,"<>Returned") -> 24410.577 | H43: =F43-G43 -> 84878.975 | I43: =COUNTIFS('Raw Data'!$B$2:$B$561,">="&B43,'Raw Data'!$B$2:$B$561,"<"&C43,'Raw Data'!$S$2:$S$561,"<>Cancelled",'Raw Data'!$S$2:$S$561,"<>Returned") -> 44
A46: Note on Revenue Recognition
A47: All financial totals in this workbook (Revenue, COGS, Gross Profit, Operating Expense, Net Profit, and the Order/Unit counts used for AOV and ASP) EXCLUDE orders with status 'Cancelled' or 'Returned'. Only 'Delivered' and 'Pending' orders are treated as recognized business. The 'Order Status Distribution' table on the Pivot Analysis sheet is the one exception - it deliberately counts orders of every status, since its purpose is to show the cancellation/return rate.
A49: Note on PivotTables & Slicers
...

Sheet Raw Data
A1: Order ID | B1: Order Date | C1: Customer ID | D1: Customer Name | E1: Region | F1: City | G1: Salesperson | H1: Product | I1: Category | J1: Quantity | K1: Unit Price | L1: Discount % | M1: Revenue | N1: COGS | O1: Gross Profit | P1: Operating Expense | Q1: Net Profit | R1: Payment Method | S1: Order Status
A2: ORD-00001 | B2: 45870 | C2: CUST-0003 | D2: Komal Chauhan | E2: Central | F2: Bhopal | G2: Arjun Mehta | H2: ViewClear 24-inch Monitor | I2: =IFERROR(INDEX(Calculations!$B$6:$B$27,MATCH(H2,Calculations!$A$6:$A$27,0)),"Unknown") -> Computer Peripherals | J2: 4 | K2: 13235.29 | L2: 0 | M2: =J2*K2*(1-L2) -> 52941.16 | N2: =J2*IFERROR(INDEX(Calculations!$C$6:$C$27,MATCH(H2,Calculations!$A$6:$A$27,0)),0) -> 28800 | O2: =M2-N2 -> 24141.16 | P2: =M2*IFERROR(INDEX(Calculations!$F$6:$F$11,MATCH(I2,Calculations!$E$6:$E$11,0)),0.1) -> 4235.2928 | Q2: =O2-P2 -> 19905.867 | R2: Credit Card | S2: Delivered
A3: ORD-00002 | B3: 45870 | C3: CUST-0033 | D3: Tanvi Kumar | E3: Central | F3: Kota | G3: Arjun Mehta | H3: FlexiCable Type-C 1m | I3: =IFERROR(INDEX(Calculations!$B$6:$B$27,MATCH(H3,Calculations!$A$6:$A$27,0)),"Unknown") -> Mobile Accessories | J3: 4 | K3: 254.39 | L3: 0.05 | M3: =J3*K3*(1-L3) -> 966.682 | N3: =J3*IFERROR(INDEX(Calculations!$C$6:$C$27,MATCH(H3,Calculations!$A$6:$A$27,0)),0) -> 360 | O3: =M3-N3 -> 606.682 | P3: =M3*IFERROR(INDEX(Calculations!$F$6:$F$11,MATCH(I3,Calculations!$E$6:$E$11,0)),0.1) -> 116.00184 | Q3: =O3-P3 -> 490.68016 | R3: UPI | S3: Delivered
A4: ORD-00003 | B4: 45870 | C4: CUST-0194 | D4: Deepak Nair | E4: Central | F4: Kota | G4: Vikram Singh | H4: ActionCam Mini 4K | I4: =IFERROR(INDEX(Calculations!$B$6:$B$27,MATCH(H4,Calculations!$A$6:$A$27,0)),"Unknown") -> Cameras | J4: 3 | K4: 7470.79 | L4: 0 | M4: =J4*K4*(1-L4) -> 22412.37 | N4: =J4*IFERROR(INDEX(Calculations!$C$6:$C$27,MATCH(H4,Calculations!$A$6:$A$27,0)),0) -> 12600 | O4: =M4-N4 -> 9812.37 | P4: =M4*IFERROR(INDEX(Calculations!$F$6:$F$11,MATCH(I4,Calculations!$E$6:$E$11,0)),0.1) -> 1680.9278 | Q4: =O4-P4 -> 8131.4423 | R4: Debit Card | S4: Delivered
A5: ORD-00004 | B5: 45870 | C5: CUST-0141 | D5: Harsh Gupta | E5: East | F5: Patna | G5: Neha Gupta | H5: SoundWave Bluetooth Speaker | I5: =IFERROR(INDEX(Calculations!$B$6:$B$27,MATCH(H5,Calculations!$A$6:$A$27,0)),"Unknown") -> Audio | J5: 1 | K5: 1865.91 | L5: 0 | M5: =J5*K5*(1-L5) -> 1865.91 | N5: =J5*IFERROR(INDEX(Calculations!$C$6:$C$27,MATCH(H5,Calculations!$A$6:$A$27,0)),0) -> 900 | O5: =M5-N5 -> 965.91 | P5: =M5*IFERROR(INDEX(Calculations!$F$6:$F$11,MATCH(I5,Calculations!$E$6:$E$11,0)),0.1) -> 186.591 | Q5: =O5-P5 -> 779.319 | R5: Credit Card | S5: Delivered
A6: ORD-00005 | B6: 45871 | C6: CUST-0102 | D6: Shreya Iyer | E6: West | F6: Mumbai | G6: Priya Nair | H6: ClickPro Wireless Mouse | I6: =IFERROR(INDEX(Calculations!$B$6:$B$27,MATCH(H6,Calculations!$A$6:$A$27,0)),"Unknown") -> Computer Peripherals | J6: 2 | K6: 769.93 | L6: 0.05 | M6: =J6*K6*(1-L6) -> 1462.867 | N6: =J6*IFERROR(INDEX(Calculations!$C$6:$C$27,MATCH(H6,Calculations!$A$6:$A$27,0)),0) -> 700 | O6: =M6-N6 -> 762.867 | P6: =M6*IFERROR(INDEX(Calculations!$F$6:$F$11,MATCH(I6,Calculations!$E$6:$E$11,0)),0.1) -> 117.02936 | Q6: =O6-P6 -> 645.83764 | R6: UPI | S6: Pending
A7: ORD-00006 | B7: 45871 | C7: CUST-0014 | D7: Harsh Joshi | E7: East | F7: Kolkata | G7: Arjun Mehta | H7: HubConnect 7-in-1 USB-C Hub | I7: =IFERROR(INDEX(Calculations!$B$6:$B$27,MATCH(H7,Calculations!$A$6:$A$27,0)),"Unknown") -> Computer Peripherals | J7: 1 | K7: 1845.62 | L7: 0.1 | M7: =J7*K7*(1-L7) -> 1661.058 | N7: =J7*IFERROR(INDEX(Calculations!$C$6:$C$27,MATCH(H7,Calculations!$A$6:$A$27,0)),0) -> 900 | O7: =M7-N7 -> 761.058 | P7: =M7*IFERROR(INDEX(Calculations!$F$6:$F$11,MATCH(I7,Calculations!$E$6:$E$11,0)),0.1) -> 132.88464 | Q7: =O7-P7 -> 628.17336 | R7: Credit Card | S7: Delivered
A8: ORD-00007 | B8: 45872 | C8: CUST-0198 | D8: Divya Sharma | E8: South | F8: Chennai | G8: Vikram Singh | H8: PowerCharge 20W Adapter | I8: =IFERROR(INDEX(Calculations!$B$6:$B$27,MATCH(H8,Calculations!$A$6:$A$27,0)),"Unknown") -> Mobile Accessories | J8: 2 | K8: 516.37 | L8: 0.15 | M8: =J8*K8*(1-L8) -> 877.829 | N8: =J8*IFERROR(INDEX(Calculations!$C$6:$C$27,MATCH(H8,Calculations!$A$6:$A$27,0)),0) -> 440 | O8: =M8-N8 -> 437.829 | P8: =M8*IFERROR(INDEX(Calculations!$F$6:$F$11,MATCH(I8,Calculations!$E$6:$E$11,0)),0.1) -> 105.33948 | Q8: =O8-P8 -> 332.48952 | R8: Credit Card | S8: Delivered
A9: ORD-00008 | B9: 45872 | C9: CUST-0104 | D9: Anjali Sharma | E9: South | F9: Chennai | G9: Suresh Kumar | H9: PulseFit Smartwatch | I9: =IFERROR(INDEX(Calculations!$B$6:$B$27,MATCH(H9,Calculations!$A$6:$A$27,0)),"Unknown") -> Wearables | J9: 1 | K9: 6502.24 | L9: 0.05 | M9: =J9*K9*(1-L9) -> 6177.128 | N9: =J9*IFERROR(INDEX(Calculations!$C$6:$C$27,MATCH(H9,Calculations!$A$6:$A$27,0)),0) -> 3800 | O9: =M9-N9 -> 2377.128 | P9: =M9*IFERROR(INDEX(Calculations!$F$6:$F$11,MATCH(I9,Calculations!$E$6:$E$11,0)),0.1) -> 555.94152 | Q9: =O9-P9 -> 1821.1865 | R9: Credit Card | S9: Delivered
A10: ORD-00009 | B10: 45873 | C10: CUST-0035 | D10: Komal Iyer | E10: Central | F10: Kota | G10: Suresh Kumar | H10: TypeMaster Mechanical Keyboard | I10: =IFERROR(INDEX(Calculations!$B$6:$B$27,MATCH(H10,Calculations!$A$6:$A$27,0)),"Unknown") -> Computer Peripherals | J10: 6 | K10: 3126.02 | L10: 0.05 | M10: =J10*K10*(1-L10) -> 17818.314 | N10: =J10*IFERROR(INDEX(Calculations!$C$6:$C$27,MATCH(H10,Calculations!$A$6:$A$27,0)),0) -> 9600 | O10: =M10-N10 -> 8218.314 | P10: =M10*IFERROR(INDEX(Calculations!$F$6:$F$11,MATCH(I10,Calculations!$E$6:$E$11,0)),0.1) -> 1425.4651 | Q10: =O10-P10 -> 6792.8489 | R10: Net Banking | S10: Pending
A11: ORD-00010 | B11: 45873 | C11: CUST-0109 | D11: Divya Bansal | E11: South | F11: Bengaluru | G11: Kavita Rao | H11: KidSafe GPS Watch | I11: =IFERROR(INDEX(Calculations!$B$6:$B$27,MATCH(H11,Calculations!$A$6:$A$27,0)),"Unknown") -> Wearables | J11: 4 | K11: 3229.52 | L11: 0.05 | M11: =J11*K11*(1-L11) -> 12272.176 | N11: =J11*IFERROR(INDEX(Calculations!$C$6:$C$27,MATCH(H11,Calculations!$A$6:$A$27,0)),0) -> 7600 | O11: =M11-N11 -> 4672.176 | P11: =M11*IFERROR(INDEX(Calculations!$F$6:$F$11,MATCH(I11,Calculations!$E$6:$E$11,0)),0.1) -> 1104.4958 | Q11: =O11-P11 -> 3567.6802 | R11: Credit Card | S11: Delivered
A12: ORD-00011 | B12: 45874 | C12: CUST-0175 | D12: Yash Kumar | E12: West | F12: Ahmedabad | G12: Rohit Sharma | H12: HomeSecure Wi-Fi Camera | I12: =IFERROR(INDEX(Calculations!$B$6:$B$27,MATCH(H12,Calculations!$A$6:$A$27,0)),"Unknown") -> Smart Home | J12: 3 | K12: 4100.45 | L12: 0.2 | M12: =J12*K12*(1-L12) -> 9841.08 | N12: =J12*IFERROR(INDEX(Calculations!$C$6:$C$27,MATCH(H12,Calculations!$A$6:$A$27,0)),0) -> 6600 | O12: =M12-N12 -> 3241.08 | P12: =M12*IFERROR(INDEX(Calculations!$F$6:$F$11,MATCH(I12,Calculations!$E$6:$E$11,0)),0.1) -> 1082.5188 | Q12: =O12-P12 -> 2158.5612 | R12: Credit Card | S12: Delivered
A13: ORD-00012 | B13: 45874 | C13: CUST-0197 | D13: Anjali Kumar | E13: Central | F13: Kota | G13: Kavita Rao | H13: HomeView 360 Camera | I13: =IFERROR(INDEX(Calculations!$B$6:$B$27,MATCH(H13,Calculations!$A$6:$A$27,0)),"Unknown") -> Cameras | J13: 5 | K13: 5563.83 | L13: 0.1 | M13: =J13*K13*(1-L13) -> 25037.235 | N13: =J13*IFERROR(INDEX(Calculations!$C$6:$C$27,MATCH(H13,Calculations!$A$6:$A$27,0)),0) -> 15500 | O13: =M13-N13 -> 9537.235 | P13: =M13*IFERROR(INDEX(Calculations!$F$6:$F$11,MATCH(I13,Calculations!$E$6:$E$11,0)),0.1) -> 1877.7926 | Q13: =O13-P13 -> 7659.4424 | R13: UPI | S13: Delivered
... A561: ORD-00560 | B561: 46234 | C561: CUST-0161 | D561: Divya Joshi | E561: West | F561: Ahmedabad | G561: Arjun Mehta | H561: ViewClear 24-inch Monitor | I561: =IFERROR(INDEX(Calculations!$B$6:$B$27,MATCH(H561,Calculations!$A$6:$A$27,0)),"Unknown") -> Computer Peripherals | J561: 2 | K561: 12931.6 | L561: 0 | M561: =J561*K561*(1-L561) -> 25863.2 | N561: =J561*IFERROR(INDEX(Calculations!$C$6:$C$27,MATCH(H561,Calculations!$A$6:$A$27,0)),0) -> 14400 | O561: =M561-N561 -> 11463.2 | P561: =M561*IFERROR(INDEX(Calculations!$F$6:$F$11,MATCH(I561,Calculations!$E$6:$E$11,0)),0.1) -> 2069.056 | Q561: =O561-P561 -> 9394.144 | R561: UPI | S561: Delivered

Sheet Pivot Analysis
A1: Pivot Analysis
A2: Pivot-style summary tables built with SUMIFS / COUNTIFS / AVERAGEIFS from Raw Data.
A4: Region-wise Performance (Recognized Revenue)
A5: Region | B5: Total Revenue | C5: Total Orders | D5: Avg Order Value
A6: North | B6: =SUMIFS('Raw Data'!$M$2:$M$561,'Raw Data'!$E$2:$E$561,A6,'Raw Data'!$S$2:$S$561,"<>Cancelled",'Raw Data'!$S$2:$S$561,"<>Returned") -> 578410.77 | C6: =COUNTIFS('Raw Data'!$E$2:$E$561,A6,'Raw Data'!$S$2:$S$561,"<>Cancelled",'Raw Data'!$S$2:$S$561,"<>Returned") -> 92 | D6: =IFERROR(B6/C6,0) -> 6287.0735
A7: South | B7: =SUMIFS('Raw Data'!$M$2:$M$561,'Raw Data'!$E$2:$E$561,A7,'Raw Data'!$S$2:$S$561,"<>Cancelled",'Raw Data'!$S$2:$S$561,"<>Returned") -> 521494.89 | C7: =COUNTIFS('Raw Data'!$E$2:$E$561,A7,'Raw Data'!$S$2:$S$561,"<>Cancelled",'Raw Data'!$S$2:$S$561,"<>Returned") -> 99 | D7: =IFERROR(B7/C7,0) -> 5267.6252
A8: East | B8: =SUMIFS('Raw Data'!$M$2:$M$561,'Raw Data'!$E$2:$E$561,A8,'Raw Data'!$S$2:$S$561,"<>Cancelled",'Raw Data'!$S$2:$S$561,"<>Returned") -> 574551.98 | C8: =COUNTIFS('Raw Data'!$E$2:$E$561,A8,'Raw Data'!$S$2:$S$561,"<>Cancelled",'Raw Data'!$S$2:$S$561,"<>Returned") -> 88 | D8: =IFERROR(B8/C8,0) -> 6528.9998
A9: West | B9: =SUMIFS('Raw Data'!$M$2:$M$561,'Raw Data'!$E$2:$E$561,A9,'Raw Data'!$S$2:$S$561,"<>Cancelled",'Raw Data'!$S$2:$S$561,"<>Returned") -> 749762.95 | C9: =COUNTIFS('Raw Data'!$E$2:$E$561,A9,'Raw Data'!$S$2:$S$561,"<>Cancelled",'Raw Data'!$S$2:$S$561,"<>Returned") -> 109 | D9: =IFERROR(B9/C9,0) -> 6878.5592
A10: Central | B10: =SUMIFS('Raw Data'!$M$2:$M$561,'Raw Data'!$E$2:$E$561,A10,'Raw Data'!$S$2:$S$561,"<>Cancelled",'Raw Data'!$S$2:$S$561,"<>Returned") -> 858494.33 | C10: =COUNTIFS('Raw Data'!$E$2:$E$561,A10,'Raw Data'!$S$2:$S$561,"<>Cancelled",'Raw Data'!$S$2:$S$561,"<>Returned") -> 96 | D10: =IFERROR(B10/C10,0) -> 8942.6492
A13: Category-wise Performance (Recognized Revenue)
A14: Category | B14: Revenue | C14: Gross Profit | D14: Gross Margin %
A15: Audio | B15: =SUMIFS('Raw Data'!$M$2:$M$561,'Raw Data'!$I$2:$I$561,A15,'Raw Data'!$S$2:$S$561,"<>Cancelled",'Raw Data'!$S$2:$S$561,"<>Returned") -> 294877.66 | C15: =SUMIFS('Raw Data'!$O$2:$O$561,'Raw Data'!$I$2:$I$561,A15,'Raw Data'!$S$2:$S$561,"<>Cancelled",'Raw Data'!$S$2:$S$561,"<>Returned") -> 136827.66 | D15: =IFERROR(C15/B15,0) -> 0.46401501
A16: Mobile Accessories | B16: =SUMIFS('Raw Data'!$M$2:$M$561,'Raw Data'!$I$2:$I$561,A16,'Raw Data'!$S$2:$S$561,"<>Cancelled",'Raw Data'!$S$2:$S$561,"<>Returned") -> 69145.095 | C16: =SUMIFS('Raw Data'!$O$2:$O$561,'Raw Data'!$I$2:$I$561,A16,'Raw Data'!$S$2:$S$561,"<>Cancelled",'Raw Data'!$S$2:$S$561,"<>Returned") -> 38765.095 | D16: =IFERROR(C16/B16,0) -> 0.56063406
A17: Computer Peripherals | B17: =SUMIFS('Raw Data'!$M$2:$M$561,'Raw Data'!$I$2:$I$561,A17,'Raw Data'!$S$2:$S$561,"<>Cancelled",'Raw Data'!$S$2:$S$561,"<>Returned") -> 967569.57 | C17: =SUMIFS('Raw Data'!$O$2:$O$561,'Raw Data'!$I$2:$I$561,A17,'Raw Data'!$S$2:$S$561,"<>Cancelled",'Raw Data'!$S$2:$S$561,"<>Returned") -> 421769.57 | D17: =IFERROR(C17/B17,0) -> 0.4359062
A18: Smart Home | B18: =SUMIFS('Raw Data'!$M$2:$M$561,'Raw Data'!$I$2:$I$561,A18,'Raw Data'!$S$2:$S$561,"<>Cancelled",'Raw Data'!$S$2:$S$561,"<>Returned") -> 605532.58 | C18: =SUMIFS('Raw Data'!$O$2:$O$561,'Raw Data'!$I$2:$I$561,A18,'Raw Data'!$S$2:$S$561,"<>Cancelled",'Raw Data'!$S$2:$S$561,"<>Returned") -> 244882.58 | D18: =IFERROR(C18/B18,0) -> 0.4044086
A19: Wearables | B19: =SUMIFS('Raw Data'!$M$2:$M$561,'Raw Data'!$I$2:$I$561,A19,'Raw Data'!$S$2:$S$561,"<>Cancelled",'Raw Data'!$S$2:$S$561,"<>Returned") -> 612326.1 | C19: =SUMIFS('Raw Data'!$O$2:$O$561,'Raw Data'!$I$2:$I$561,A19,'Raw Data'!$S$2:$S$561,"<>Cancelled",'Raw Data'!$S$2:$S$561,"<>Returned") -> 228526.1 | D19: =IFERROR(C19/B19,0) -> 0.37320979
A20: Cameras | B20: =SUMIFS('Raw Data'!$M$2:$M$561,'Raw Data'!$I$2:$I$561,A20,'Raw Data'!$S$2:$S$561,"<>Cancelled",'Raw Data'!$S$2:$S$561,"<>Returned") -> 733263.91 | C20: =SUMIFS('Raw Data'!$O$2:$O$561,'Raw Data'!$I$2:$I$561,A20,'Raw Data'!$S$2:$S$561,"<>Cancelled",'Raw Data'!$S$2:$S$561,"<>Returned") -> 294463.91 | D20: =IFERROR(C20/B20,0) -> 0.40157971
A23: Product-wise Performance (Recognized Revenue)
A24: Product | B24: Revenue | C24: Gross Profit | D24: Units Sold
A25: BassPro Wireless Earbuds | B25: =SUMIFS('Raw Data'!$M$2:$M$561,'Raw Data'!$H$2:$H$561,A25,'Raw Data'!$S$2:$S$561,"<>Cancelled",'Raw Data'!$S$2:$S$561,"<>Returned") -> 38978.717 | C25: =SUMIFS('Raw Data'!$O$2:$O$561,'Raw Data'!$H$2:$H$561,A25,'Raw Data'!$S$2:$S$561,"<>Cancelled",'Raw Data'!$S$2:$S$561,"<>Returned") -> 18178.716 | D25: =SUMIFS('Raw Data'!$J$2:$J$561,'Raw Data'!$H$2:$H$561,A25,'Raw Data'!$S$2:$S$561,"<>Cancelled",'Raw Data'!$S$2:$S$561,"<>Returned") -> 32
A26: SoundWave Bluetooth Speaker | B26: =SUMIFS('Raw Data'!$M$2:$M$561,'Raw Data'!$H$2:$H$561,A26,'Raw Data'!$S$2:$S$561,"<>Cancelled",'Raw Data'!$S$2:$S$561,"<>Returned") -> 75200.12 | C26: =SUMIFS('Raw Data'!$O$2:$O$561,'Raw Data'!$H$2:$H$561,A26,'Raw Data'!$S$2:$S$561,"<>Cancelled",'Raw Data'!$S$2:$S$561,"<>Returned") -> 37400.12 | D26: =SUMIFS('Raw Data'!$J$2:$J$561,'Raw Data'!$H$2:$H$561,A26,'Raw Data'!$S$2:$S$561,"<>Cancelled",'Raw Data'!$S$2:$S$561,"<>Returned") -> 42
A27: StudioMax Over-Ear Headphones | B27: =SUMIFS('Raw Data'!$M$2:$M$561,'Raw Data'!$H$2:$H$561,A27,'Raw Data'!$S$2:$S$561,"<>Cancelled",'Raw Data'!$S$2:$S$561,"<>Returned") -> 138387.01 | C27: =SUMIFS('Raw Data'!$O$2:$O$561,'Raw Data'!$H$2:$H$561,A27,'Raw Data'!$S$2:$S$561,"<>Cancelled",'Raw Data'!$S$2:$S$561,"<>Returned") -> 62787.014 | D27: =SUMIFS('Raw Data'!$J$2:$J$561,'Raw Data'!$H$2:$H$561,A27,'Raw Data'!$S$2:$S$561,"<>Cancelled",'Raw Data'!$S$2:$S$561,"<>Returned") -> 54
A28: EchoBeat Neckband | B28: =SUMIFS('Raw Data'!$M$2:$M$561,'Raw Data'!$H$2:$H$561,A28,'Raw Data'!$S$2:$S$561,"<>Cancelled",'Raw Data'!$S$2:$S$561,"<>Returned") -> 42311.81 | C28: =SUMIFS('Raw Data'!$O$2:$O$561,'Raw Data'!$H$2:$H$561,A28,'Raw Data'!$S$2:$S$561,"<>Cancelled",'Raw Data'!$S$2:$S$561,"<>Returned") -> 18461.809 | D28: =SUMIFS('Raw Data'!$J$2:$J$561,'Raw Data'!$H$2:$H$561,A28,'Raw Data'!$S$2:$S$561,"<>Cancelled",'Raw Data'!$S$2:$S$561,"<>Returned") -> 53
A29: PowerCharge 20W Adapter | B29: =SUMIFS('Raw Data'!$M$2:$M$561,'Raw Data'!$H$2:$H$561,A29,'Raw Data'!$S$2:$S$561,"<>Cancelled",'Raw Data'!$S$2:$S$561,"<>Returned") -> 24143.932 | C29: =SUMIFS('Raw Data'!$O$2:$O$561,'Raw Data'!$H$2:$H$561,A29,'Raw Data'!$S$2:$S$561,"<>Cancelled",'Raw Data'!$S$2:$S$561,"<>Returned") -> 12703.932 | D29: =SUMIFS('Raw Data'!$J$2:$J$561,'Raw Data'!$H$2:$H$561,A29,'Raw Data'!$S$2:$S$561,"<>Cancelled",'Raw Data'!$S$2:$S$561,"<>Returned") -> 52
A30: FlexiCable Type-C 1m | B30: =SUMIFS('Raw Data'!$M$2:$M$561,'Raw Data'!$H$2:$H$561,A30,'Raw Data'!$S$2:$S$561,"<>Cancelled",'Raw Data'!$S$2:$S$561,"<>Returned") -> 15052.809 | C30: =SUMIFS('Raw Data'!$O$2:$O$561,'Raw Data'!$H$2:$H$561,A30,'Raw Data'!$S$2:$S$561,"<>Cancelled",'Raw Data'!$S$2:$S$561,"<>Returned") -> 9202.809 | D30: =SUMIFS('Raw Data'!$J$2:$J$561,'Raw Data'!$H$2:$H$561,A30,'Raw Data'!$S$2:$S$561,"<>Cancelled",'Raw Data'!$S$2:$S$561,"<>Returned") -> 65
A31: ArmorShield Phone Case | B31: =SUMIFS('Raw Data'!$M$2:$M$561,'Raw Data'!$H$2:$H$561,A31,'Raw Data'!$S$2:$S$561,"<>Cancelled",'Raw Data'!$S$2:$S$561,"<>Returned") -> 13440.138 | C31: =SUMIFS('Raw Data'!$O$2:$O$561,'Raw Data'!$H$2:$H$561,A31,'Raw Data'!$S$2:$S$561,"<>Cancelled",'Raw Data'!$S$2:$S$561,"<>Returned") -> 7850.138 | D31: =SUMIFS('Raw Data'!$J$2:$J$561,'Raw Data'!$H$2:$H$561,A31,'Raw Data'!$S$2:$S$561,"<>Cancelled",'Raw Data'!$S$2:$S$561,"<>Returned") -> 43
A32: MagGrip Phone Stand | B32: =SUMIFS('Raw Data'!$M$2:$M$561,'Raw Data'!$H$2:$H$561,A32,'Raw Data'!$S$2:$S$561,"<>Cancelled",'Raw Data'!$S$2:$S$561,"<>Returned") -> 16508.216 | C32: =SUMIFS('Raw Data'!$O$2:$O$561,'Raw Data'!$H$2:$H$561,A32,'Raw Data'!$S$2:$S$561,"<>Cancelled",'Raw Data'!$S$2:$S$561,"<>Returned") -> 9008.216 | D32: =SUMIFS('Raw Data'!$J$2:$J$561,'Raw Data'!$H$2:$H$561,A32,'Raw Data'!$S$2:$S$561,"<>Cancelled",'Raw Data'!$S$2:$S$561,"<>Returned") -> 50
A33: ClickPro Wireless Mouse | B33: =SUMIFS('Raw Data'!$M$2:$M$561,'Raw Data'!$H$2:$H$561,A33,'Raw Data'!$S$2:$S$561,"<>Cancelled",'Raw Data'!$S$2:$S$561,"<>Returned") -> 24917.513 | C33: =SUMIFS('Raw Data'!$O$2:$O$561,'Raw Data'!$H$2:$H$561,A33,'Raw Data'!$S$2:$S$561,"<>Cancelled",'Raw Data'!$S$2:$S$561,"<>Returned") -> 13017.513 | D33: =SUMIFS('Raw Data'!$J$2:$J$561,'Raw Data'!$H$2:$H$561,A33,'Raw Data'!$S$2:$S$561,"<>Cancelled",'Raw Data'!$S$2:$S$561,"<>Returned") -> 34
A34: TypeMaster Mechanical Keyboard | B34: =SUMIFS('Raw Data'!$M$2:$M$561,'Raw Data'!$H$2:$H$561,A34,'Raw Data'!$S$2:$S$561,"<>Cancelled",'Raw Data'!$S$2:$S$561,"<>Returned") -> 144525.8 | C34: =SUMIFS('Raw Data'!$O$2:$O$561,'Raw Data'!$H$2:$H$561,A34,'Raw Data'!$S$2:$S$561,"<>Cancelled",'Raw Data'!$S$2:$S$561,"<>Returned") -> 67725.804 | D34: =SUMIFS('Raw Data'!$J$2:$J$561,'Raw Data'!$H$2:$H$561,A34,'Raw Data'!$S$2:$S$561,"<>Cancelled",'Raw Data'!$S$2:$S$561,"<>Returned") -> 48
A35: ViewClear 24-inch Monitor | B35: =SUMIFS('Raw Data'!$M$2:$M$561,'Raw Data'!$H$2:$H$561,A35,'Raw Data'!$S$2:$S$561,"<>Cancelled",'Raw Data'!$S$2:$S$561,"<>Returned") -> 672143.28 | C35: =SUMIFS('Raw Data'!$O$2:$O$561,'Raw Data'!$H$2:$H$561,A35,'Raw Data'!$S$2:$S$561,"<>Cancelled",'Raw Data'!$S$2:$S$561,"<>Returned") -> 283343.28 | D35: =SUMIFS('Raw Data'!$J$2:$J$561,'Raw Data'!$H$2:$H$561,A35,'Raw Data'!$S$2:$S$561,"<>Cancelled",'Raw Data'!$S$2:$S$561,"<>Returned") -> 54
A36: HubConnect 7-in-1 USB-C Hub | B36: =SUMIFS('Raw Data'!$M$2:$M$561,'Raw Data'!$H$2:$H$561,A36,'Raw Data'!$S$2:$S$561,"<>Cancelled",'Raw Data'!$S$2:$S$561,"<>Returned") -> 94469.356 | C36: =SUMIFS('Raw Data'!$O$2:$O$561,'Raw Data'!$H$2:$H$561,A36,'Raw Data'!$S$2:$S$561,"<>Cancelled",'Raw Data'!$S$2:$S$561,"<>Returned") -> 43169.357 | D36: =SUMIFS('Raw Data'!$J$2:$J$561,'Raw Data'!$H$2:$H$561,A36,'Raw Data'!$S$2:$S$561,"<>Cancelled",'Raw Data'!$S$2:$S$561,"<>Returned") -> 57
... A46: HomeView 360 Camera | B46: =SUMIFS('Raw Data'!$M$2:$M$561,'Raw Data'!$H$2:$H$561,A46,'Raw Data'!$S$2:$S$561,"<>Cancelled",'Raw Data'!$S$2:$S$561,"<>Returned") -> 225879.85 | C46: =SUMIFS('Raw Data'!$O$2:$O$561,'Raw Data'!$H$2:$H$561,A46,'Raw Data'!$S$2:$S$561,"<>Cancelled",'Raw Data'!$S$2:$S$561,"<>Returned") -> 89479.853 | D46: =SUMIFS('Raw Data'!$J$2:$J$561,'Raw Data'!$H$2:$H$561,A46,'Raw Data'!$S$2:$S$561,"<>Cancelled",'Raw Data'!$S$2:$S$561,"<>Returned") -> 44
A49: Salesperson-wise Performance (Recognized Revenue)
A50: Salesperson | B50: Revenue | C50: Net Profit | D50: Total Orders
A51: Ananya Verma | B51: =SUMIFS('Raw Data'!$M$2:$M$561,'Raw Data'!$G$2:$G$561,A51,'Raw Data'!$S$2:$S$561,"<>Cancelled",'Raw Data'!$S$2:$S$561,"<>Returned") -> 444261.1 | C51: =SUMIFS('Raw Data'!$Q$2:$Q$561,'Raw Data'!$G$2:$G$561,A51,'Raw Data'!$S$2:$S$561,"<>Cancelled",'Raw Data'!$S$2:$S$561,"<>Returned") -> 151337.06 | D51: =COUNTIFS('Raw Data'!$G$2:$G$561,A51,'Raw Data'!$S$2:$S$561,"<>Cancelled",'Raw Data'!$S$2:$S$561,"<>Returned") -> 61
A52: Arjun Mehta | B52: =SUMIFS('Raw Data'!$M$2:$M$561,'Raw Data'!$G$2:$G$561,A52,'Raw Data'!$S$2:$S$561,"<>Cancelled",'Raw Data'!$S$2:$S$561,"<>Returned") -> 358342.76 | C52: =SUMIFS('Raw Data'!$Q$2:$Q$561,'Raw Data'!$G$2:$G$561,A52,'Raw Data'!$S$2:$S$561,"<>Cancelled",'Raw Data'!$S$2:$S$561,"<>Returned") -> 121710.14 | D52: =COUNTIFS('Raw Data'!$G$2:$G$561,A52,'Raw Data'!$S$2:$S$561,"<>Cancelled",'Raw Data'!$S$2:$S$561,"<>Returned") -> 54
A53: Kavita Rao | B53: =SUMIFS('Raw Data'!$M$2:$M$561,'Raw Data'!$G$2:$G$561,A53,'Raw Data'!$S$2:$S$561,"<>Cancelled",'Raw Data'!$S$2:$S$561,"<>Returned") -> 395378.95 | C53: =SUMIFS('Raw Data'!$Q$2:$Q$561,'Raw Data'!$G$2:$G$561,A53,'Raw Data'!$S$2:$S$561,"<>Cancelled",'Raw Data'!$S$2:$S$561,"<>Returned") -> 133433.23 | D53: =COUNTIFS('Raw Data'!$G$2:$G$561,A53,'Raw Data'!$S$2:$S$561,"<>Cancelled",'Raw Data'!$S$2:$S$561,"<>Returned") -> 61
A54: Neha Gupta | B54: =SUMIFS('Raw Data'!$M$2:$M$561,'Raw Data'!$G$2:$G$561,A54,'Raw Data'!$S$2:$S$561,"<>Cancelled",'Raw Data'!$S$2:$S$561,"<>Returned") -> 452782.07 | C54: =SUMIFS('Raw Data'!$Q$2:$Q$561,'Raw Data'!$G$2:$G$561,A54,'Raw Data'!$S$2:$S$561,"<>Cancelled",'Raw Data'!$S$2:$S$561,"<>Returned") -> 147665.49 | D54: =COUNTIFS('Raw Data'!$G$2:$G$561,A54,'Raw Data'!$S$2:$S$561,"<>Cancelled",'Raw Data'!$S$2:$S$561,"<>Returned") -> 63
A55: Priya Nair | B55: =SUMIFS('Raw Data'!$M$2:$M$561,'Raw Data'!$G$2:$G$561,A55,'Raw Data'!$S$2:$S$561,"<>Cancelled",'Raw Data'!$S$2:$S$561,"<>Returned") -> 422272.84 | C55: =SUMIFS('Raw Data'!$Q$2:$Q$561,'Raw Data'!$G$2:$G$561,A55,'Raw Data'!$S$2:$S$561,"<>Cancelled",'Raw Data'!$S$2:$S$561,"<>Returned") -> 133658.72 | D55: =COUNTIFS('Raw Data'!$G$2:$G$561,A55,'Raw Data'!$S$2:$S$561,"<>Cancelled",'Raw Data'!$S$2:$S$561,"<>Returned") -> 58
A56: Rohit Sharma | B56: =SUMIFS('Raw Data'!$M$2:$M$561,'Raw Data'!$G$2:$G$561,A56,'Raw Data'!$S$2:$S$561,"<>Cancelled",'Raw Data'!$S$2:$S$561,"<>Returned") -> 317498.93 | C56: =SUMIFS('Raw Data'!$Q$2:$Q$561,'Raw Data'!$G$2:$G$561,A56,'Raw Data'!$S$2:$S$561,"<>Cancelled",'Raw Data'!$S$2:$S$561,"<>Returned") -> 98292.577 | D56: =COUNTIFS('Raw Data'!$G$2:$G$561,A56,'Raw Data'!$S$2:$S$561,"<>Cancelled",'Raw Data'!$S$2:$S$561,"<>Returned") -> 56
...

Sheet KPI Summary
A1: KPI Summary
A2: All figures are calculated live from Raw Data. Revenue, cost and profit figures exclude Cancelled and Returned orders (see note below).
A4: KPI | B4: Value | C4: Formula Logic
A5: Total Revenue | B5: =SUMIFS('Raw Data'!$M$2:$M$561,'Raw Data'!$S$2:$S$561,"<>Cancelled",'Raw Data'!$S$2:$S$561,"<>Returned") -> 3282714.9 | C5: SUMIFS of Revenue, excluding Cancelled/Returned orders
A6: Total COGS | B6: =SUMIFS('Raw Data'!$N$2:$N$561,'Raw Data'!$S$2:$S$561,"<>Cancelled",'Raw Data'!$S$2:$S$561,"<>Returned") -> 1917480 | C6: SUMIFS of COGS, excluding Cancelled/Returned orders
A7: Gross Profit | B7: =B5-B6 -> 1365234.9 | C7: Total Revenue - Total COGS
A8: Gross Margin % | B8: =IFERROR(B7/B5,0) -> 0.41588592 | C8: Gross Profit / Total Revenue
A9: Operating Expenses | B9: =SUMIFS('Raw Data'!$P$2:$P$561,'Raw Data'!$S$2:$S$561,"<>Cancelled",'Raw Data'!$S$2:$S$561,"<>Returned") -> 291903.47 | C9: SUMIFS of Operating Expense, excluding Cancelled/Returned orders
A10: Net Profit | B10: =B7-B9 -> 1073331.5 | C10: Gross Profit - Operating Expenses
A11: Net Profit Margin % | B11: =IFERROR(B10/B5,0) -> 0.32696456 | C11: Net Profit / Total Revenue
A12: Total Orders Placed (All Statuses) | B12: =COUNTA('Raw Data'!$A$2:$A$561) -> 560 | C12: COUNTA of Order ID column - includes Cancelled/Returned (volume metric)
A13: Recognized Orders (Delivered + Pending) | B13: =COUNTIFS('Raw Data'!$S$2:$S$561,"<>Cancelled",'Raw Data'!$S$2:$S$561,"<>Returned") -> 484 | C13: COUNTIFS excluding Cancelled/Returned - the order count behind Revenue
A14: Cancelled / Returned Orders | B14: =B12-B13 -> 76 | C14: Total Orders Placed - Recognized Orders
A15: Total Units Sold | B15: =SUMIFS('Raw Data'!$J$2:$J$561,'Raw Data'!$S$2:$S$561,"<>Cancelled",'Raw Data'!$S$2:$S$561,"<>Returned") -> 1145 | C15: SUMIFS of Quantity, excluding Cancelled/Returned orders
A16: Average Order Value (AOV) | B16: =IFERROR(B5/B13,0) -> 6782.4688 | C16: Total Revenue / Recognized Orders
A17: Average Selling Price (ASP) | B17: =IFERROR(B5/B15,0) -> 2866.9999 | C17: Total Revenue / Total Units Sold
A19: Revenue Recognition Rule
A20: Cancelled and Returned orders are excluded from every financial KPI above, as well as from Gross/Net Profit and margin calculations - only Delivered and Pending orders are treated as recognized revenue. 'Total Orders Placed' is shown separately as an operational volume metric that includes all order statuses.

Sheet Dashboard
A1: Nexora Retail Solutions
A2: Business Finance & Sales Performance Dashboard | Analysis Period: Aug 2025 - Jul 2026
A3: Figures reflect Delivered and Pending orders only; Cancelled and Returned orders are excluded from Revenue, COGS, Gross Profit, Operating Expense and Net Profit (see KPI Summary sheet for the full revenue-recognition rule).
A5: Total Revenue | C5: Total COGS | E5: Gross Profit | G5: Net Profit | I5: Net Profit Margin | K5: Recognized Orders | M5: Total Units Sold | O5: Avg Order Value
A6: ='KPI Summary'!B5 -> 3282714.9 | C6: ='KPI Summary'!B6 -> 1917480 | E6: ='KPI Summary'!B7 -> 1365234.9 | G6: ='KPI Summary'!B10 -> 1073331.5 | I6: ='KPI Summary'!B11 -> 0.32696456 | K6: ='KPI Summary'!B13 -> 484 | M6: ='KPI Summary'!B15 -> 1145 | O6: ='KPI Summary'!B16 -> 6782.4688

Sheet Insights
B2: Business Insights
B3: Every statement below is calculated directly from the Raw Data sheet - nothing is manually typed in.
B5: Automated Insight Calculations
B6: Highest revenue month
B7: ="The highest revenue month was "&INDEX('Pivot Analysis'!$A$80:$A$91,MATCH(MAX('Pivot Analysis'!$B$80:$B$91),'Pivot Analysis'!$B$80:$B$91,0))&" with revenue of Rs. "&TEXT(MAX('Pivot Analysis'!$B$80:$B$91),"#,##0") -> The highest revenue month was Apr-26 with revenue of Rs. 384,240
B8: Lowest revenue month
B9: ="The lowest revenue month was "&INDEX('Pivot Analysis'!$A$80:$A$91,MATCH(MIN('Pivot Analysis'!$B$80:$B$91),'Pivot Analysis'!$B$80:$B$91,0))&" with revenue of Rs. "&TEXT(MIN('Pivot Analysis'!$B$80:$B$91),"#,##0") -> The lowest revenue month was Nov-25 with revenue of Rs. 194,016
B10: Highest-performing region
B11: ="The highest-performing region by revenue was "&INDEX('Pivot Analysis'!$A$6:$A$10,MATCH(MAX('Pivot Analysis'!$B$6:$B$10),'Pivot Analysis'!$B$6:$B$10,0))&" with revenue of Rs. "&TEXT(MAX('Pivot Analysis'!$B$6:$B$10),"#,##0") -> The highest-performing region by revenue was Central with revenue of Rs. 858,494
B12: Most profitable category (by gross margin %)
B13: ="The category with the highest gross margin % was "&INDEX('Pivot Analysis'!$A$15:$A$20,MATCH(MAX('Pivot Analysis'!$D$15:$D$20),'Pivot Analysis'!$D$15:$D$20,0))&" at "&TEXT(MAX('Pivot Analysis'!$D$15:$D$20),"0.0%")&" gross margin" -> The category with the highest gross margin % was Mobile Accessories at 56.1% gross margin
B14: Top product by revenue
B15: ="The top product by revenue was "&INDEX('Pivot Analysis'!$A$25:$A$46,MATCH(MAX('Pivot Analysis'!$B$25:$B$46),'Pivot Analysis'!$B$25:$B$46,0))&" with revenue of Rs. "&TEXT(MAX('Pivot Analysis'!$B$25:$B$46),"#,##0") -> The top product by revenue was ViewClear 24-inch Monitor with revenue of Rs. 672,143
B16: Top product by gross profit
B17: ="The top product by gross profit was "&INDEX('Pivot Analysis'!$A$25:$A$46,MATCH(MAX('Pivot Analysis'!$C$25:$C$46),'Pivot Analysis'!$C$25:$C$46,0))&" with gross profit of Rs. "&TEXT(MAX('Pivot Analysis'!$C$25:$C$46),"#,##0") -> The top product by gross profit was ViewClear 24-inch Monitor with gross profit of Rs. 283,343
B18: Best salesperson (by revenue)
B19: ="The top-performing salesperson by revenue was "&INDEX('Pivot Analysis'!$A$51:$A$58,MATCH(MAX('Pivot Analysis'!$B$51:$B$58),'Pivot Analysis'!$B$51:$B$58,0))&" with revenue of Rs. "&TEXT(MAX('Pivot Analysis'!$B$51:$B$58),"#,##0") -> The top-performing salesperson by revenue was Suresh Kumar with revenue of Rs. 484,478
B20: Average order value
B21: ="The average order value across recognized (Delivered + Pending) orders is Rs. "&TEXT('KPI Summary'!$B$16,"#,##0")&", based on "&TEXT('KPI Summary'!$B$13,"#,##0")&" recognized orders" -> The average order value across recognized (Delivered + Pending) orders is Rs. 6,782, based on 484 recognized orders
B22: Overall profit margin
B23: ="The overall net profit margin for the period is "&TEXT('KPI Summary'!$B$11,"0.0%")&" on recognized revenue of Rs. "&TEXT('KPI Summary'!$B$5,"#,##0") -> The overall net profit margin for the period is 32.7% on recognized revenue of Rs. 3,282,715
B24: Major expense driver
B25: ="Operating expenses total Rs. "&TEXT('KPI Summary'!$B$9,"#,##0")&", which is "&TEXT('KPI Summary'!$B$9/'KPI Summary'!$B$5,"0.0%")&" of recognized revenue across all categories combined" -> Operating expenses total Rs. 291,903, which is 8.9% of recognized revenue across all categories combined
B26: Order cancellation / return pattern
B27: ="Cancelled and Returned orders together account for "&TEXT('KPI Summary'!$B$14/'KPI Summary'!$B$12,"0.0%")&" of the "&TEXT('KPI Summary'!$B$12,"#,##0")&" total orders placed ("&TEXT('KPI Summary'!$B$14,"#,##0")&" orders), and are excluded from all revenue and profit figures in this workbook" -> Cancelled and Returned orders together account for 13.6% of the 560 total orders placed (76 orders), and are excluded from all revenue and profit figures in this workbook
B29: Interpretation Notes
B30: These insights update automatically if the Raw Data changes - they are formulas, not typed conclusions.
B31: Monthly revenue shows normal month-to-month fluctuation rather than a strong trend, which is realistic for a 12-month window with randomly distributed orders across products and regions.
B32: Gross margin differs by category mainly because of differing unit cost ratios per product - categories with lower-cost accessories naturally show higher gross margin % than higher-cost electronics categories.
B33: The cancellation/return rate is a useful operational KPI - in a real business this would be investigated by product and by salesperson to find the root cause.
B34: No conclusion in this sheet goes beyond what the Raw Data and Pivot Analysis tables directly support - there is no reference to information outside the 560-row dataset.
